<?xml version="1.0" encoding="UTF-8"?>
<!-- Generated by org.testng.reporters.JUnitReportReporter -->
<testsuite hostname="DESKTOP-8AF4MIK" failures="1" tests="1" name="testPackage.TC_001_Login2" time="7.284" errors="0" timestamp="2024-11-19T16:18:12 IST" skipped="0">
  <testcase classname="testPackage.TC_001_Login2" name="validatelogin" time="7.284">
    <failure message="expected [Invalid ] but found [Invalid Credentials]" type="java.lang.AssertionError">
      <![CDATA[java.lang.AssertionError: expected [Invalid ] but found [Invalid Credentials]
at org.testng.Assert.fail(Assert.java:111)
at org.testng.Assert.failNotEquals(Assert.java:1578)
at org.testng.Assert.assertEqualsImpl(Assert.java:150)
at org.testng.Assert.assertEquals(Assert.java:132)
at org.testng.Assert.assertEquals(Assert.java:656)
at org.testng.Assert.assertEquals(Assert.java:666)
at pageObjects.PG_001_Login.verifytoastmessage(PG_001_Login.java:120)
at testPackage.TC_001_Login2.validatelogin(TC_001_Login2.java:31)
at java.base/jdk.internal.reflect.DirectMethodHandleAccessor.invoke(DirectMethodHandleAccessor.java:103)
at java.base/java.lang.reflect.Method.invoke(Method.java:580)
at org.testng.internal.invokers.MethodInvocationHelper.invokeMethod(MethodInvocationHelper.java:141)
at org.testng.internal.invokers.TestInvoker.invokeMethod(TestInvoker.java:686)
at org.testng.internal.invokers.TestInvoker.invokeTestMethod(TestInvoker.java:230)
at org.testng.internal.invokers.TestMethodWithDataProviderMethodWorker.call(TestMethodWithDataProviderMethodWorker.java:81)
at org.testng.internal.thread.Async$AsyncTask.run(Async.java:34)
at java.base/java.util.concurrent.ThreadPoolExecutor.runWorker(ThreadPoolExecutor.java:1144)
at java.base/java.util.concurrent.ThreadPoolExecutor$Worker.run(ThreadPoolExecutor.java:642)
at java.base/java.lang.Thread.run(Thread.java:1583)
]]>
    </failure>
  </testcase> <!-- validatelogin -->
</testsuite> <!-- testPackage.TC_001_Login2 -->
